[2024-01-08T08:43:08.571+0000] {taskinstance.py:1171} INFO - Dependencies all met for <TaskInstance: fetching_cleaning.Data_Cleaning manual__2024-01-08T08:38:03.459400+00:00 [queued]>
[2024-01-08T08:43:08.576+0000] {taskinstance.py:1171} INFO - Dependencies all met for <TaskInstance: fetching_cleaning.Data_Cleaning manual__2024-01-08T08:38:03.459400+00:00 [queued]>
[2024-01-08T08:43:08.577+0000] {taskinstance.py:1368} INFO - 
--------------------------------------------------------------------------------
[2024-01-08T08:43:08.577+0000] {taskinstance.py:1369} INFO - Starting attempt 2 of 2
[2024-01-08T08:43:08.577+0000] {taskinstance.py:1370} INFO - 
--------------------------------------------------------------------------------
[2024-01-08T08:43:08.584+0000] {taskinstance.py:1389} INFO - Executing <Task(PythonOperator): Data_Cleaning> on 2024-01-08 08:38:03.459400+00:00
[2024-01-08T08:43:08.596+0000] {standard_task_runner.py:52} INFO - Started process 330 to run task
[2024-01-08T08:43:08.622+0000] {standard_task_runner.py:79} INFO - Running: ['***', 'tasks', 'run', 'fetching_cleaning', 'Data_Cleaning', 'manual__2024-01-08T08:38:03.459400+00:00', '--job-id', '7', '--raw', '--subdir', 'DAGS_FOLDER/DAG.py', '--cfg-path', '/tmp/tmpzba309g4', '--error-file', '/tmp/tmp6aawoj6i']
[2024-01-08T08:43:08.627+0000] {standard_task_runner.py:80} INFO - Job 7: Subtask Data_Cleaning
[2024-01-08T08:43:08.806+0000] {task_command.py:371} INFO - Running <TaskInstance: fetching_cleaning.Data_Cleaning manual__2024-01-08T08:38:03.459400+00:00 [running]> on host 13eafc15112b
[2024-01-08T08:43:08.888+0000] {taskinstance.py:1583} INFO - Exporting the following env vars:
AIRFLOW_CTX_DAG_OWNER=saepul
AIRFLOW_CTX_DAG_ID=fetching_cleaning
AIRFLOW_CTX_TASK_ID=Data_Cleaning
AIRFLOW_CTX_EXECUTION_DATE=2024-01-08T08:38:03.459400+00:00
AIRFLOW_CTX_TRY_NUMBER=2
AIRFLOW_CTX_DAG_RUN_ID=manual__2024-01-08T08:38:03.459400+00:00
[2024-01-08T08:43:08.957+0000] {taskinstance.py:1902} ERROR - Task failed with exception
Traceback (most recent call last):
  File "/home/airflow/.local/lib/python3.7/site-packages/airflow/operators/python.py", line 171, in execute
    return_value = self.execute_callable()
  File "/home/airflow/.local/lib/python3.7/site-packages/airflow/operators/python.py", line 189, in execute_callable
    return self.python_callable(*self.op_args, **self.op_kwargs)
  File "/opt/airflow/dags/steps/clean.py", line 15, in cleaning_data
    df['CustomerID'] = df['CustomerID'].str.replace('')
  File "/home/airflow/.local/lib/python3.7/site-packages/pandas/core/generic.py", line 5487, in __getattr__
    return object.__getattribute__(self, name)
  File "/home/airflow/.local/lib/python3.7/site-packages/pandas/core/accessor.py", line 181, in __get__
    accessor_obj = self._accessor(obj)
  File "/home/airflow/.local/lib/python3.7/site-packages/pandas/core/strings/accessor.py", line 168, in __init__
    self._inferred_dtype = self._validate(data)
  File "/home/airflow/.local/lib/python3.7/site-packages/pandas/core/strings/accessor.py", line 225, in _validate
    raise AttributeError("Can only use .str accessor with string values!")
AttributeError: Can only use .str accessor with string values!
[2024-01-08T08:43:08.975+0000] {taskinstance.py:1412} INFO - Marking task as FAILED. dag_id=fetching_cleaning, task_id=Data_Cleaning, execution_date=20240108T083803, start_date=20240108T084308, end_date=20240108T084308
[2024-01-08T08:43:08.982+0000] {standard_task_runner.py:97} ERROR - Failed to execute job 7 for task Data_Cleaning (Can only use .str accessor with string values!; 330)
[2024-01-08T08:43:08.998+0000] {local_task_job.py:156} INFO - Task exited with return code 1
[2024-01-08T08:43:09.019+0000] {local_task_job.py:279} INFO - 0 downstream tasks scheduled from follow-on schedule check
