[2024-01-08T08:33:53.820+0000] {taskinstance.py:1171} INFO - Dependencies all met for <TaskInstance: fetching_cleaning.Fetch_from_Postgresql manual__2024-01-08T08:33:51.685602+00:00 [queued]>
[2024-01-08T08:33:53.826+0000] {taskinstance.py:1171} INFO - Dependencies all met for <TaskInstance: fetching_cleaning.Fetch_from_Postgresql manual__2024-01-08T08:33:51.685602+00:00 [queued]>
[2024-01-08T08:33:53.827+0000] {taskinstance.py:1368} INFO - 
--------------------------------------------------------------------------------
[2024-01-08T08:33:53.827+0000] {taskinstance.py:1369} INFO - Starting attempt 1 of 2
[2024-01-08T08:33:53.827+0000] {taskinstance.py:1370} INFO - 
--------------------------------------------------------------------------------
[2024-01-08T08:33:53.834+0000] {taskinstance.py:1389} INFO - Executing <Task(PythonOperator): Fetch_from_Postgresql> on 2024-01-08 08:33:51.685602+00:00
[2024-01-08T08:33:53.841+0000] {standard_task_runner.py:52} INFO - Started process 207 to run task
[2024-01-08T08:33:53.843+0000] {standard_task_runner.py:79} INFO - Running: ['***', 'tasks', 'run', 'fetching_cleaning', 'Fetch_from_Postgresql', 'manual__2024-01-08T08:33:51.685602+00:00', '--job-id', '2', '--raw', '--subdir', 'DAGS_FOLDER/DAG.py', '--cfg-path', '/tmp/tmp9pg30wqt', '--error-file', '/tmp/tmpu9735p0_']
[2024-01-08T08:33:53.845+0000] {standard_task_runner.py:80} INFO - Job 2: Subtask Fetch_from_Postgresql
[2024-01-08T08:33:53.919+0000] {task_command.py:371} INFO - Running <TaskInstance: fetching_cleaning.Fetch_from_Postgresql manual__2024-01-08T08:33:51.685602+00:00 [running]> on host 13eafc15112b
[2024-01-08T08:33:53.973+0000] {taskinstance.py:1583} INFO - Exporting the following env vars:
AIRFLOW_CTX_DAG_OWNER=saepul
AIRFLOW_CTX_DAG_ID=fetching_cleaning
AIRFLOW_CTX_TASK_ID=Fetch_from_Postgresql
AIRFLOW_CTX_EXECUTION_DATE=2024-01-08T08:33:51.685602+00:00
AIRFLOW_CTX_TRY_NUMBER=1
AIRFLOW_CTX_DAG_RUN_ID=manual__2024-01-08T08:33:51.685602+00:00
[2024-01-08T08:33:53.979+0000] {taskinstance.py:1902} ERROR - Task failed with exception
Traceback (most recent call last):
  File "/home/airflow/.local/lib/python3.7/site-packages/sqlalchemy/engine/base.py", line 1803, in _execute_context
    cursor, statement, parameters, context
  File "/home/airflow/.local/lib/python3.7/site-packages/sqlalchemy/engine/default.py", line 719, in do_execute
    cursor.execute(statement, parameters)
psycopg2.errors.UndefinedTable: relation "table_final_project" does not exist
LINE 1: select * from table_final_project
                      ^


The above exception was the direct cause of the following exception:

Traceback (most recent call last):
  File "/home/airflow/.local/lib/python3.7/site-packages/airflow/operators/python.py", line 171, in execute
    return_value = self.execute_callable()
  File "/home/airflow/.local/lib/python3.7/site-packages/airflow/operators/python.py", line 189, in execute_callable
    return self.python_callable(*self.op_args, **self.op_kwargs)
  File "/opt/airflow/dags/steps/fetch.py", line 14, in fetching_data
    df = pd.read_sql_query("select * from table_final_project", conn) # Memilih kolom yang akan di tarik datanya
  File "/home/airflow/.local/lib/python3.7/site-packages/pandas/io/sql.py", line 443, in read_sql_query
    dtype=dtype,
  File "/home/airflow/.local/lib/python3.7/site-packages/pandas/io/sql.py", line 1579, in read_query
    result = self.execute(*args)
  File "/home/airflow/.local/lib/python3.7/site-packages/pandas/io/sql.py", line 1424, in execute
    return self.connectable.execution_options().execute(*args, **kwargs)
  File "/home/airflow/.local/lib/python3.7/site-packages/sqlalchemy/engine/base.py", line 1279, in execute
    future=False,
  File "/home/airflow/.local/lib/python3.7/site-packages/sqlalchemy/engine/base.py", line 1585, in _exec_driver_sql
    distilled_parameters,
  File "/home/airflow/.local/lib/python3.7/site-packages/sqlalchemy/engine/base.py", line 1846, in _execute_context
    e, statement, parameters, cursor, context
  File "/home/airflow/.local/lib/python3.7/site-packages/sqlalchemy/engine/base.py", line 2027, in _handle_dbapi_exception
    sqlalchemy_exception, with_traceback=exc_info[2], from_=e
  File "/home/airflow/.local/lib/python3.7/site-packages/sqlalchemy/util/compat.py", line 207, in raise_
    raise exception
  File "/home/airflow/.local/lib/python3.7/site-packages/sqlalchemy/engine/base.py", line 1803, in _execute_context
    cursor, statement, parameters, context
  File "/home/airflow/.local/lib/python3.7/site-packages/sqlalchemy/engine/default.py", line 719, in do_execute
    cursor.execute(statement, parameters)
sqlalchemy.exc.ProgrammingError: (psycopg2.errors.UndefinedTable) relation "table_final_project" does not exist
LINE 1: select * from table_final_project
                      ^

[SQL: select * from table_final_project]
(Background on this error at: https://sqlalche.me/e/14/f405)
[2024-01-08T08:33:53.994+0000] {taskinstance.py:1412} INFO - Marking task as UP_FOR_RETRY. dag_id=fetching_cleaning, task_id=Fetch_from_Postgresql, execution_date=20240108T083351, start_date=20240108T083353, end_date=20240108T083353
[2024-01-08T08:33:54.010+0000] {standard_task_runner.py:97} ERROR - Failed to execute job 2 for task Fetch_from_Postgresql ((psycopg2.errors.UndefinedTable) relation "table_final_project" does not exist
LINE 1: select * from table_final_project
                      ^

[SQL: select * from table_final_project]
(Background on this error at: https://sqlalche.me/e/14/f405); 207)
[2024-01-08T08:33:54.057+0000] {local_task_job.py:156} INFO - Task exited with return code 1
[2024-01-08T08:33:54.083+0000] {local_task_job.py:279} INFO - 0 downstream tasks scheduled from follow-on schedule check
